<?xml version="1.0"?>
<robot xmlns:xacro="http://ros.org/wiki/xacro" name="prius">
  <!--- Surface properties must come first? -->
  <gazebo reference="front_left_wheel">
    <mu1>5</mu1>
    <mu2>5</mu2>
    <minDepth>0.005</minDepth>
    <kp>1e8</kp>
  </gazebo>
  <gazebo reference="front_right_wheel">
    <mu1>5</mu1>
    <mu2>5</mu2>
    <minDepth>0.005</minDepth>
    <kp>1e8</kp>
  </gazebo>
  <gazebo reference="rear_left_wheel">
    <mu1>5</mu1>
    <mu2>5</mu2>
    <minDepth>0.005</minDepth>
    <kp>1e8</kp>
  </gazebo>
  <gazebo reference="rear_right_wheel">
    <mu1>5</mu1>
    <mu2>5</mu2>
    <minDepth>0.005</minDepth>
    <kp>1e8</kp>
  </gazebo>

  <link name="base_link">
    <inertial>
      <mass value="0.1"/>
      <inertia ixx="0.001" ixy="0.0" ixz="0.0" iyy="0.001" iyz="0.0" izz="0.001"/>
    </inertial>
  </link>
  <joint name="base_link_connection" type="fixed">
    <parent link="base_link"/>
    <child link="chassis"/>
    <origin xyz="1.45 0 0" rpy="0 0 1.57"/>
    <axis xyz="1 0 0"/>
  </joint>

  <link name="chassis">
    <visual>
      <origin xyz="0 0 0" rpy="0 0 0"/>
      <geometry>
        <mesh filename="package://prius_description/meshes/hybrid_body.obj" scale="0.01 0.01 0.01"/>
      </geometry>
    </visual>

    <collision name="chassis">
      <origin xyz="0.0 0.05 0.625" rpy="0 0 0"/>
      <geometry>
        <box size="1.7526 2.1 0.95"/>
      </geometry>
    </collision>

    <collision name="front_bumper">
      <origin xyz="0.0 -2.0 0.458488" rpy="0.0 0 0"/>
      <geometry>
        <box size="1.337282 0.48 0.566691"/>
      </geometry>
    </collision>

    <collision name="hood">
      <origin xyz="0.0 -1.900842 0.676305" rpy="0.341247 0 0"/>
      <geometry>
        <box size="1.597968 0.493107 0.265468"/>
      </geometry>
    </collision>

    <collision name="windshield">
      <origin xyz="0.0 -0.875105 1.032268" rpy="0.335476 0 0"/>
      <geometry>
        <box size="1.168381 1.654253 0.272347"/>
      </geometry>
    </collision>

    <collision name="top_front">
      <origin xyz="0.0 0.161236 1.386042" rpy="0.135030 0 0"/>
      <geometry>
        <box size="1.279154 0.625988 0.171868"/>
      </geometry>
    </collision>

    <collision name="top_rear">
      <origin xyz="0.0 0.817696 1.360069" rpy="-0.068997 0 0"/>
      <geometry>
        <box size="1.285130 0.771189 0.226557"/>
      </geometry>
    </collision>

    <collision name="rear_window">
      <origin xyz="0.0 1.640531 1.175126" rpy="-0.262017 0 0"/>
      <geometry>
        <box size="1.267845 1.116344 0.244286"/>
      </geometry>
    </collision>

    <collision name="trunk">
      <origin xyz="0.0 1.637059 0.888180" rpy="0.0 0 0"/>
      <geometry>
        <box size="1.788064 1.138988 0.482746"/>
      </geometry>
    </collision>

    <collision name="back_bumper">
      <origin xyz="0.0 2.054454 0.577870" rpy="0.0 0 0"/>
      <geometry>
        <box size="1.781650 0.512093 0.581427"/>
      </geometry>
    </collision>

    <inertial>
      <mass value="135.60"/>
      <origin xyz="0 0 0.48" rpy="0 0 1.5708"/>
      <inertia ixx="258.113354740" ixy="0.0" ixz="0.0" iyy="59.130846112" iyz="0.0" izz="26.8195008628"/>
    </inertial>
  </link>
  <link name="fl_axle">
    <inertial>
      <mass value=".1"/>
      <origin xyz="0 0 0"/>
      <inertia ixx="0.004" ixy="0.0" ixz="0.0" iyy="0.004" iyz="0.0" izz="0.004"/>
    </inertial>
  </link>
  <link name="fr_axle">
    <inertial>
      <mass value=".1"/>
      <origin xyz="0 0 0"/>
      <inertia ixx="0.004" ixy="0.0" ixz="0.0" iyy="0.004" iyz="0.0" izz="0.004"/>
    </inertial>
  </link>
  <link name="front_left_wheel">
    <inertial>
      <mass value="1.1"/>
      <origin xyz="0 0 0"/>
      <inertia ixx="0.58631238" ixy="0.0" ixz="0.0" iyy="0.33552910" iyz="0.0" izz="0.33552910"/>
    </inertial>
    <collision name="front_left_wheel_collision">
      <geometry>
        <sphere radius="0.31265"/>
      </geometry>
    </collision>
    <visual>
      <origin xyz="0 0 0" rpy="0 0 0"/>
      <geometry>
        <mesh filename="package://prius_description/meshes/wheel.obj" scale="0.01 0.01 0.01"/>
      </geometry>
    </visual>
  </link>
  <link name="front_right_wheel">
    <inertial>
      <mass value="1.1"/>
      <origin xyz="0 0 0"/>
      <inertia ixx="0.58631238" ixy="0.0" ixz="0.0" iyy="0.33552910" iyz="0.0" izz="0.33552910"/>
    </inertial>
    <collision name="front_right_wheel_collision">
      <geometry>
        <sphere radius="0.31265"/>
      </geometry>
    </collision>
    <visual>
      <origin xyz="0 0 0" rpy="0 0 0"/>
      <geometry>
        <mesh filename="package://prius_description/meshes/wheel.obj" scale="0.01 0.01 0.01"/>
      </geometry>
    </visual>
  </link>
  <link name="rear_left_wheel">
    <inertial>
      <mass value="1.1"/>
      <origin xyz="0 0 0"/>
      <inertia ixx="0.58631238" ixy="0.0" ixz="0.0" iyy="0.33552910" iyz="0.0" izz="0.33552910"/>
    </inertial>
    <collision name="rear_left_wheel_collision">
      <geometry>
        <sphere radius="0.31265"/>
      </geometry>
    </collision>
    <visual>
      <origin xyz="0 0 0" rpy="0 0 0"/>
      <geometry>
        <mesh filename="package://prius_description/meshes/wheel.obj" scale="0.01 0.01 0.01"/>
      </geometry>
    </visual>
  </link>
  <link name="rear_right_wheel">
    <inertial>
      <mass value="1.1"/>
      <origin xyz="0 0 0"/>
      <inertia ixx="0.58631238" ixy="0.0" ixz="0.0" iyy="0.33552910" iyz="0.0" izz="0.33552910"/>
    </inertial>
    <collision name="rear_right_wheel_collision">
      <geometry>
        <sphere radius="0.31265"/>
      </geometry>
    </collision>
    <visual>
      <origin xyz="0 0 0" rpy="0 0 0"/>
      <geometry>
        <mesh filename="package://prius_description/meshes/wheel.obj" scale="0.01 0.01 0.01"/>
      </geometry>
    </visual>
  </link>
  <link name="steering_wheel">
    <inertial>
      <mass value="0.10"/>
      <inertia ixx="0.14583300" ixy="0.0" ixz="0.0" iyy="0.14583300" iyz="0.0" izz="0.125"/>
    </inertial>
    <visual>
      <origin xyz="0 0 0" rpy="1.302101 0 0"/>
      <geometry>
        <mesh filename="package://prius_description/meshes/steering_wheel.obj" scale="0.01 0.01 0.01"/>
      </geometry>
    </visual>
  </link>

  <joint name="steering_joint" type="continuous">
    <origin xyz="0.357734 -0.627868 0.988243" rpy="-1.302101 0 0"/>
    <parent link="chassis"/>
    <child link="steering_wheel"/>
    <axis xyz="0 0 1"/>
    <limit lower="-7.85" upper="7.85" effort="10000000" velocity="1000000"/>
  </joint>

  <joint name="front_left_steer_joint" type="continuous">
    <parent link="chassis"/>
    <child link="fl_axle"/>
    <origin xyz="0.767 -1.41 0.3" rpy="0 0 0"/>
    <axis xyz="0 0 1"/>
    <limit lower="-0.8727" upper="0.8727" effort="10000000" velocity="1000000"/>
  </joint>
  <joint name="front_right_steer_joint" type="continuous">
    <parent link="chassis"/>
    <child link="fr_axle"/>
    <origin xyz="-0.767 -1.41 0.3" rpy="0 0 0"/>
    <axis xyz="0 0 1"/>
    <limit lower="-0.8727" upper="0.8727" effort="10000000" velocity="1000000"/>
  </joint>
  <joint name="front_left_wheel_joint" type="continuous">
    <parent link="fl_axle"/>
    <child link="front_left_wheel"/>
    <origin xyz="0 0 0" rpy="0 0 0"/>
    <axis xyz="1 0 0"/>
  </joint>
  <joint name="front_right_wheel_joint" type="continuous">
    <parent link="fr_axle"/>
    <child link="front_right_wheel"/>
    <origin xyz="0 0 0" rpy="0 0 0"/>
    <axis xyz="1 0 0"/>
  </joint>
  <joint name="rear_left_wheel_joint" type="continuous">
    <parent link="chassis"/>
    <child link="rear_left_wheel"/>
    <origin xyz="0.793 1.45 0.3" rpy="0 0 0"/>
    <axis xyz="1 0 0"/>
    <dynamics damping="4.0" friction="0.0"/>
  </joint>
  <joint name="rear_right_wheel_joint" type="continuous">
    <parent link="chassis"/>
    <child link="rear_right_wheel"/>
    <origin xyz="-0.793 1.45 0.3" rpy="0 0 0"/>
    <axis xyz="1 0 0"/>
    <dynamics damping="4.0" friction="0.0"/>
  </joint>

  <!-- Sensor links and fixed joints -->
  <link name="center_laser_link">
    <inertial>
      <mass value="1"/>
      <inertia ixx="0.001" ixy="0.0" ixz="0.0" iyy="0.001" iyz="0.0" izz="0.001"/>
    </inertial>
  </link>
  <joint name="center_laser_joint" type="fixed">
    <parent link="chassis"/>
    <child link="center_laser_link"/>
    <origin xyz="0 -2.2 0.6" rpy="0 0 1.5707"/>
  </joint>

  <gazebo reference="base_link_connection">
    <disableFixedJointLumping>true</disableFixedJointLumping>
  </gazebo>

  <link name="front_camera_link">
    <inertial>
      <mass value="1"/>
      <inertia ixx="0.001" ixy="0.0" ixz="0.0" iyy="0.001" iyz="0.0" izz="0.001"/>
    </inertial>
  </link>
  <joint name="front_camera_joint" type="fixed">
    <parent link="chassis"/>
    <child link="front_camera_link"/>
    <origin xyz="0 -0.5 1.8" rpy="0 0.12 -1.5707"/>
  </joint>
  <link name="front_camera_link_optical">
    <inertial>
      <mass value="1"/>
      <inertia ixx="0.001" ixy="0.0" ixz="0.0" iyy="0.001" iyz="0.0" izz="0.001"/>
    </inertial>
  </link>
  <joint name="front_camera_optical_joint" type="fixed">
    <origin xyz="0 0 0" rpy="-1.5707 0 -1.5707"/>
    <parent link="front_camera_link"/>
    <child link="front_camera_link_optical"/>
  </joint>

  <gazebo>
    <plugin name="pruis_hybrid_drive" filename="libPriusHybridPlugin.so">
      <chassis>chassis</chassis>
      <front_left_wheel>front_left_wheel_joint</front_left_wheel>
      <front_right_wheel>front_right_wheel_joint</front_right_wheel>
      <front_left_wheel_steering>front_left_steer_joint</front_left_wheel_steering>
      <front_right_wheel_steering>front_right_steer_joint</front_right_wheel_steering>
      <back_left_wheel>rear_left_wheel_joint</back_left_wheel>
      <back_right_wheel>rear_right_wheel_joint</back_right_wheel>
      <steering_wheel>steering_joint</steering_wheel>
      <chassis_aero_force_gain>0.63045</chassis_aero_force_gain>
      <front_torque>859.4004393000001</front_torque>
      <back_torque>0</back_torque>
      <max_speed>37.998337013956565</max_speed>
      <max_steer>0.6458</max_steer>
      <flwheel_steering_p_gain>1e4</flwheel_steering_p_gain>
      <frwheel_steering_p_gain>1e4</frwheel_steering_p_gain>
      <flwheel_steering_i_gain>0</flwheel_steering_i_gain>
      <frwheel_steering_i_gain>0</frwheel_steering_i_gain>
      <flwheel_steering_d_gain>3e2</flwheel_steering_d_gain>
      <frwheel_steering_d_gain>3e2</frwheel_steering_d_gain>
    </plugin>
  </gazebo>

  <gazebo>
    <plugin name="joint_state_publisher" filename="libgazebo_ros_joint_state_publisher.so">
      <joint_name>rear_right_wheel_joint</joint_name>
      <joint_name>rear_left_wheel_joint</joint_name>
      <joint_name>front_right_wheel_joint</joint_name>
      <joint_name>front_left_wheel_joint</joint_name>
      <joint_name>front_right_steer_joint</joint_name>
      <joint_name>front_left_steer_joint</joint_name>
      <joint_name>steering_joint</joint_name>
      <update_rate>60.0</update_rate>
      <always_on>true</always_on>
    </plugin>
  </gazebo>

  <gazebo reference="center_laser_link">
    <sensor name='center_laser_sensor' type='ray'>
      <ray>
        <scan>
          <horizontal>
            <samples>360</samples>
            <resolution>1</resolution>
            <min_angle>-3.14</min_angle>
            <max_angle>3.14</max_angle>
          </horizontal>
        </scan>
        <range>
          <min>0.2</min>
          <max>30</max>
          <resolution>0.01</resolution>
        </range>
      </ray>
      <plugin name='center_laser' filename='libgazebo_ros_ray_sensor.so'>
        <ros>
          <remapping>~/out:=/prius/center_laser/scan</remapping>
        </ros>
        <output_type>sensor_msgs/LaserScan</output_type>
        <frame_name>center_laser_link</frame_name>
      </plugin>
      <always_on>1</always_on>
      <update_rate>10</update_rate>
      <visualize>0</visualize>
    </sensor>
  </gazebo>

  <gazebo reference="front_camera_link">
    <sensor type="camera" name="front_camera_sensor">
      <update_rate>30.0</update_rate>
      <camera name="front_camera">
        <horizontal_fov>1.85</horizontal_fov>
        <image>
          <width>1280</width>
          <height>960</height>
          <format>R8G8B8</format>
        </image>
        <clip>
          <near>0.02</near>
          <far>300</far>
        </clip>
        <!--
        <noise>
          <type>gaussian</type>
          <mean>0.0</mean>
          <stddev>0.03</stddev>
        </noise>
        -->
      </camera>
      <plugin name="front_camera_controller" filename="libgazebo_ros_camera.so">
        <always_on>false</always_on>
        <update_rate>0.0</update_rate>
        <camera_name>pylon_camera_node</camera_name>
        <ros>
          <argument>image_raw:=image_rect</argument><!-- this one is publishing rectified images directly -->
        </ros>
        <frame_name>front_camera_link_optical</frame_name>
        <hack_baseline>0.07</hack_baseline>
      </plugin>
    </sensor>
  </gazebo>

</robot>
